Workbook

Sheet Tv-listen
A1: Mærke | B1: Serie | C1: Navn | D1: Modelkoder | E1: Tommer | F1: Årgang | G1: Højde (cm) | H1: VESA bredde (mm) | I1: VESA højde (mm) | J1: Nederste hul over underkant (cm) | K1: Øverste hul over underkant (cm) | L1: Kildetype | M1: Kilde | N1: Kildetekst
A2: Hisense | B2: E7KQ | C2: E7KQ (2023) | D2: 43E7KQ, 43E7KQTUK | E2: 43 | F2: 2023 | G2: 56 | H2: 200 | I2: 300 | J2: 12 | K2: =IF(ISNUMBER(J2),J2+I2/10,"") | L2: kundemålt | N2: Kollegamålt 24/9-2026: VESA 200×300 mm, nederste hul 12 cm fra underkant. Højden 56 cm er anslået ud fra 43″, ikke målt.
A3: LG | B3: LR65 | C3: LR65 (2023) | D3: LG LR65 32″ 2023 | E3: 32 | F3: 2023 | G3: 42.8 | H3: 200 | I3: 200 | J3: 11.1 | K3: =IF(ISNUMBER(J3),J3+I3/10,"") | L3: producentens mål | M3: LG-tegning 2023 | N3: LG's officielle bagside-tegning 2023: X1 = 111 mm. Højden er regnet som X1 + VESA + W (ca. 1 cm usikkerhed).
A4: LG | B4: NANO73/NANO75/NANO77 | C4: NANO73/NANO75/NANO77 (2023) | D4: LG NANO73/NANO75/NANO77 86″ 2023 | E4: 86 | F4: 2023 | G4: 110.2 | H4: 600 | I4: 400 | J4: 27 | K4: =IF(ISNUMBER(J4),J4+I4/10,"") | L4: producentens mål | M4: LG-tegning 2023 | N4: LG's officielle bagside-tegning 2023: X1 = 270 mm. Højden er regnet som X1 + VESA + W (ca. 1 cm usikkerhed).
A5: LG | B5: NANO73/NANO75/NANO77 | C5: NANO73/NANO75/NANO77 (2023) | D5: LG NANO73/NANO75/NANO77 75″ 2023 | E5: 75 | F5: 2023 | G5: 96.2 | H5: 400 | I5: 400 | J5: 27.7 | K5: =IF(ISNUMBER(J5),J5+I5/10,"") | L5: producentens mål | M5: LG-tegning 2023 | N5: LG's officielle bagside-tegning 2023: X1 = 277 mm. Højden er regnet som X1 + VESA + W (ca. 1 cm usikkerhed).
A6: LG | B6: NANO73/NANO75/NANO77 | C6: NANO73/NANO75/NANO77 (2023) | D6: LG NANO73/NANO75/NANO77 70″ 2023 | E6: 70 | F6: 2023 | G6: 90.5 | H6: 400 | I6: 400 | J6: 24 | K6: =IF(ISNUMBER(J6),J6+I6/10,"") | L6: producentens mål | M6: LG-tegning 2023 | N6: LG's officielle bagside-tegning 2023: X1 = 240 mm. Højden er regnet som X1 + VESA + W (ca. 1 cm usikkerhed).
A7: LG | B7: NANO73/NANO75/NANO77 | C7: NANO73/NANO75/NANO77 (2023) | D7: LG NANO73/NANO75/NANO77 65″ 2023 | E7: 65 | F7: 2023 | G7: 83.5 | H7: 300 | I7: 300 | J7: 15.9 | K7: =IF(ISNUMBER(J7),J7+I7/10,"") | L7: producentens mål | M7: LG-tegning 2023 | N7: LG's officielle bagside-tegning 2023: X1 = 159 mm. Højden er regnet som X1 + VESA + W (ca. 1 cm usikkerhed).
A8: LG | B8: NANO73/NANO75/NANO77 | C8: NANO73/NANO75/NANO77 (2023) | D8: LG NANO73/NANO75/NANO77 55″ 2023 | E8: 55 | F8: 2023 | G8: 71.2 | H8: 300 | I8: 300 | J8: 15.9 | K8: =IF(ISNUMBER(J8),J8+I8/10,"") | L8: producentens mål | M8: LG-tegning 2023 | N8: LG's officielle bagside-tegning 2023: X1 = 159 mm. Højden er regnet som X1 + VESA + W (ca. 1 cm usikkerhed).
A9: LG | B9: NANO73/NANO75/NANO77 | C9: NANO73/NANO75/NANO77 (2023) | D9: LG NANO73/NANO75/NANO77 50″ 2023 | E9: 50 | F9: 2023 | G9: 64.9 | H9: 200 | I9: 200 | J9: 22.5 | K9: =IF(ISNUMBER(J9),J9+I9/10,"") | L9: producentens mål | M9: LG-tegning 2023 | N9: LG's officielle bagside-tegning 2023: X1 = 225 mm. Højden er regnet som X1 + VESA + W (ca. 1 cm usikkerhed).
A10: LG | B10: NANO73/NANO75/NANO77 | C10: NANO73/NANO75/NANO77 (2023) | D10: LG NANO73/NANO75/NANO77 43″ 2023 | E10: 43 | F10: 2023 | G10: 56.2 | H10: 200 | I10: 200 | J10: 21.3 | K10: =IF(ISNUMBER(J10),J10+I10/10,"") | L10: producentens mål | M10: LG-tegning 2023 | N10: LG's officielle bagside-tegning 2023: X1 = 213 mm. Højden er regnet som X1 + VESA + W (ca. 1 cm usikkerhed).
A11: LG | B11: NANO75 | C11: NanoCell 4K NANO75 | D11: 55NANO756QA, 55NANO759QA, 55NANO756QC | E11: 55 | F11: 2022 | G11: 70.5 | H11: 300 | I11: 300 | K11: =IF(ISNUMBER(J11),J11+I11/10,"") | L11: estimat
A12: LG | B12: NANO76 | C12: NANO76 | D12: 86NANO766QA, 86NANO769QA | E12: 86 | F12: 2022 | G12: 110.4 | H12: 600 | I12: 400 | K12: =IF(ISNUMBER(J12),J12+I12/10,"") | L12: estimat
A13: LG | B13: NANO76 | C13: NANO76 | D13: 75NANO766QA, 75NANO769QA | E13: 75 | F13: 2022 | G13: 96.4 | H13: 400 | I13: 400 | K13: =IF(ISNUMBER(J13),J13+I13/10,"") | L13: estimat
A14: LG | B14: NANO76 | C14: NANO76 | D14: 65NANO766QA, 65NANO769QA | E14: 65 | F14: 2022 | G14: 83.8 | H14: 300 | I14: 300 | K14: =IF(ISNUMBER(J14),J14+I14/10,"") | L14: estimat
A15: LG | B15: NANO76 | C15: NANO76 | D15: 55NANO766QA, 55NANO766QA--BUNDLE1, 55NANO769QA, 55NANO766QA--BUNDLE | E15: 55 | F15: 2022 | G15: 71.5 | H15: 300 | I15: 300 | J15: 15.8 | K15: =IF(ISNUMBER(J15),J15+I15/10,"") | L15: billedmålt | M15: LG | N15: Billedmålt på LG-foto: nederste VESA-hul 15,8 cm fra underkant, målt ud fra VESA 300×300 som skala. Usikkerhed ca. ±1 cm.
A16: LG | B16: NANO76 | C16: NANO76 | D16: 50NANO766QA, 50NANO769QA | E16: 50 | F16: 2022 | G16: 65.1 | H16: 200 | I16: 200 | K16: =IF(ISNUMBER(J16),J16+I16/10,"") | L16: estimat
A17: LG | B17: NANO76 | C17: NANO76 | D17: 43NANO766QA, 43NANO769QA | E17: 43 | F17: 2022 | G17: 56.4 | H17: 200 | I17: 200 | K17: =IF(ISNUMBER(J17),J17+I17/10,"") | L17: estimat
A18: LG | B18: NANO80 | C18: NANO80 | D18: 75NANO80A6B | E18: 75 | F18: 2026 | G18: 96.4 | H18: 400 | I18: 400 | K18: =IF(ISNUMBER(J18),J18+I18/10,"") | L18: estimat
A19: LG | B19: NANO80 | C19: NANO80 | D19: 65NANO80A6B | E19: 65 | F19: 2026 | G19: 83.8 | H19: 300 | I19: 300 | J19: 15.9 | K19: =IF(ISNUMBER(J19),J19+I19/10,"") | L19: billedmålt | M19: Which? | N19: Billedmålt på Which?-foto (lg-65nano80a6b): nederste VESA-hul 15,9 cm fra underkant, målt ud fra VESA 300×300 som skala. Usikkerhed ca. ±1 cm. Billedkontrol (LG): 16,1 cm.
A20: LG | B20: NANO80 | C20: NANO80 | D20: 55NANO80A6B | E20: 55 | F20: 2026 | G20: 71.5 | H20: 300 | I20: 300 | J20: 15.9 | K20: =IF(ISNUMBER(J20),J20+I20/10,"") | L20: billedmålt | M20: Which? | N20: Billedmålt på Which?-foto (lg-55nano80a6b): nederste VESA-hul 15,9 cm fra underkant, målt ud fra VESA 300×300 som skala. Usikkerhed ca. ±1 cm. Billedkontrol (LG): 16 cm.
A21: LG | B21: NANO80 | C21: NANO80 | D21: 50NANO80A6B | E21: 50 | F21: 2026 | G21: 65.1 | H21: 200 | I21: 200 | J21: 22.4 | K21: =IF(ISNUMBER(J21),J21+I21/10,"") | L21: billedmålt | M21: Which? | N21: Billedmålt på Which?-foto (lg-50nano80a6b): nederste VESA-hul 22,4 cm fra underkant, målt ud fra VESA 200×200 som skala. Usikkerhed ca. ±1 cm. Billedkontrol (LG): 22,5 cm.
A22: LG | B22: NANO80 | C22: NANO80 | D22: 43NANO80A6B | E22: 43 | F22: 2026 | G22: 56.4 | H22: 200 | I22: 200 | J22: 21.2 | K22: =IF(ISNUMBER(J22),J22+I22/10,"") | L22: billedmålt | M22: Which? | N22: Billedmålt på Which?-foto (lg-43nano80a6b): nederste VESA-hul 21,2 cm fra underkant, målt ud fra VESA 200×200 som skala. Usikkerhed ca. ±1 cm. Billedkontrol (LG): 21,4 cm.
A23: LG | B23: NANO81 | C23: NANO81 | D23: 86NANO81T6A | E23: 86 | F23: 2024 | G23: 110.4 | H23: 600 | I23: 400 | K23: =IF(ISNUMBER(J23),J23+I23/10,"") | L23: estimat
A24: LG | B24: NANO81 | C24: NANO81 | D24: 86NANO81A6A | E24: 86 | F24: 2025 | G24: 110.4 | H24: 600 | I24: 400 | K24: =IF(ISNUMBER(J24),J24+I24/10,"") | L24: estimat
A25: LG | B25: NANO81 | C25: NANO81 | D25: 75NANO816QA, 75NANO819QA | E25: 75 | F25: 2022 | G25: 96.4 | H25: 400 | I25: 400 | K25: =IF(ISNUMBER(J25),J25+I25/10,"") | L25: estimat
A26: LG | B26: NANO81 | C26: NANO81 | D26: 75NANO81T6A | E26: 75 | F26: 2024 | G26: 96.4 | H26: 400 | I26: 400 | K26: =IF(ISNUMBER(J26),J26+I26/10,"") | L26: estimat
A27: LG | B27: NANO81 | C27: NANO81 | D27: 75NANO81A6A | E27: 75 | F27: 2025 | G27: 96.4 | H27: 400 | I27: 400 | K27: =IF(ISNUMBER(J27),J27+I27/10,"") | L27: estimat
A28: LG | B28: NANO81 | C28: NANO81 | D28: 65NANO816QA, 65NANO819QA | E28: 65 | F28: 2022 | G28: 83.8 | H28: 300 | I28: 300 | K28: =IF(ISNUMBER(J28),J28+I28/10,"") | L28: estimat
A29: LG | B29: NANO81 | C29: NANO81 | D29: 65NANO81T6A | E29: 65 | F29: 2024 | G29: 83.8 | H29: 300 | I29: 300 | K29: =IF(ISNUMBER(J29),J29+I29/10,"") | L29: estimat
A30: LG | B30: NANO81 | C30: NANO81 | D30: 65NANO81A6A | E30: 65 | F30: 2025 | G30: 83.8 | H30: 300 | I30: 300 | J30: 15.9 | K30: =IF(ISNUMBER(J30),J30+I30/10,"") | L30: billedmålt | M30: Which? | N30: Billedmålt på Which?-foto (lg-65nano81a6a): nederste VESA-hul 15,9 cm fra underkant, målt ud fra VESA 300×300 som skala. Usikkerhed ca. ±1 cm.
A31: LG | B31: NANO81 | C31: NANO81 | D31: 55NANO816QA, 55NANO819QA | E31: 55 | F31: 2022 | G31: 71.5 | H31: 300 | I31: 300 | K31: =IF(ISNUMBER(J31),J31+I31/10,"") | L31: estimat
A32: LG | B32: NANO81 | C32: NANO81 | D32: 55NANO81T6A | E32: 55 | F32: 2024 | G32: 71.5 | H32: 300 | I32: 300 | J32: 15.9 | K32: =IF(ISNUMBER(J32),J32+I32/10,"") | L32: billedmålt | M32: MediaMarkt | N32: Billedmålt på MediaMarkt-foto (foto af 55NANO81T6AA): nederste VESA-hul 15,9 cm fra underkant, målt ud fra VESA 300×300 som skala. Usikkerhed ca. ±1 cm. Billedkontrol (LG): 15,9 cm.
A33: LG | B33: NANO81 | C33: NANO81 | D33: 55NANO81A6A | E33: 55 | F33: 2025 | G33: 71.5 | H33: 300 | I33: 300 | J33: 15.9 | K33: =IF(ISNUMBER(J33),J33+I33/10,"") | L33: billedmålt | M33: Which? | N33: Billedmålt på Which?-foto (lg-55nano81a6a): nederste VESA-hul 15,9 cm fra underkant, målt ud fra VESA 300×300 som skala. Usikkerhed ca. ±1 cm.
A34: LG | B34: NANO81 | C34: NANO81 | D34: 50NANO816QA, 50NANO819QA | E34: 50 | F34: 2022 | G34: 65.1 | H34: 200 | I34: 200 | K34: =IF(ISNUMBER(J34),J34+I34/10,"") | L34: estimat
A35: LG | B35: NANO81 | C35: NANO81 | D35: 50NANO81T6A | E35: 50 | F35: 2024 | G35: 65.1 | H35: 200 | I35: 200 | K35: =IF(ISNUMBER(J35),J35+I35/10,"") | L35: estimat
A36: LG | B36: NANO81 | C36: NANO81 | D36: 50NANO81A6A | E36: 50 | F36: 2025 | G36: 65.1 | H36: 200 | I36: 200 | J36: 22.4 | K36: =IF(ISNUMBER(J36),J36+I36/10,"") | L36: billedmålt | M36: Which? | N36: Billedmålt på Which?-foto (lg-50nano81a6a): nederste VESA-hul 22,4 cm fra underkant, målt ud fra VESA 200×200 som skala. Usikkerhed ca. ±1 cm.
A37: LG | B37: NANO81 | C37: NANO81 | D37: 43NANO81T6A | E37: 43 | F37: 2024 | G37: 56.4 | H37: 200 | I37: 200 | K37: =IF(ISNUMBER(J37),J37+I37/10,"") | L37: estimat
A38: LG | B38: NANO81 | C38: NANO81 | D38: 43NANO81A6A | E38: 43 | F38: 2025 | G38: 56.4 | H38: 200 | I38: 200 | J38: 21.2 | K38: =IF(ISNUMBER(J38),J38+I38/10,"") | L38: billedmålt | M38: Which? | N38: Billedmålt på Which?-foto (lg-43nano81a6a): nederste VESA-hul 21,2 cm fra underkant, målt ud fra VESA 200×200 som skala. Usikkerhed ca. ±1 cm.
A39: LG | B39: NANO82 | C39: NANO82 | D39: 75NANO82T6B | E39: 75 | F39: 2026 | G39: 96.4 | H39: 400 | I39: 400 | K39: =IF(ISNUMBER(J39),J39+I39/10,"") | L39: estimat
A40: LG | B40: NANO82 | C40: NANO82 | D40: 65NANO82T6B | E40: 65 | F40: 2026 | G40: 83.8 | H40: 300 | I40: 300 | K40: =IF(ISNUMBER(J40),J40+I40/10,"") | L40: estimat
...

Sheet Om listen
A1: Tv-listen bag tv-højde-værktøjet
A2: Opdateret 22/10-2026. Højde og VESA er producenternes tal. Hulplaceringen kommer fra kilderne nedenfor.
A3: Sådan bruges den: underkant på stander = standerens øverste hul − (position − 1) × 2,5 cm − 'Øverste hul over underkant'. Overkant = underkant + højde.
A4: Er kilderne uenige om VESA, gælder i denne rækkefølge: kundemåling, LG's tegning, hulmønstret på fotoet, LG's produktside, Icecat.
A6: Kildetype | B6: Antal tv | C6: Hvad det betyder | D6: Usikkerhed
A7: kundemålt | B7: =COUNTIF('Tv-listen'!$L$2:$L$803,A7) | C7: Målt med tommestok af en kunde eller kollega. | D7: ca. ±0,5 cm (skøn)
A8: producentens mål | B8: =COUNTIF('Tv-listen'!$L$2:$L$803,A8) | C8: LG's officielle bagside-tegning (2023-modeller) og Sonys måltabeller (2022-modeller). | D8: producentens egne mm-mål
A9: billedmålt | B9: =COUNTIF('Tv-listen'!$L$2:$L$803,A9) | C9: Målt på et lige bagside-foto (Which?, LG, Icecat, MediaMarkt, Elgiganten) med VESA-hullerne som målestok. | D9: ca. ±1 cm
A10: 3D-model | B10: =COUNTIF('Tv-listen'!$L$2:$L$803,A10) | C10: Målt på Samsungs egen 3D-model af tv'et fra samsung.com. | D10: ca. ±1,5 cm
A11: samme bagside | B11: =COUNTIF('Tv-listen'!$L$2:$L$803,A11) | C11: Regional variant af et målt tv: samme serie, årgang, størrelse og VESA. | D11: som det målte tv
A12: reference | B12: =COUNTIF('Tv-listen'!$L$2:$L$803,A12) | C12: Fra Equals' måltabel. | D12: ca. ±1 cm
A13: estimat | B13: =COUNTIF('Tv-listen'!$L$2:$L$803,A13) | C13: Ingen målt placering. Værktøjet estimerer ud fra mærke. | D13: op til 10 cm
A14: I alt | B14: =SUM(B7:B13) | C14: Tv-listen har 802 rækker.
